Workbook
Name a: [1]工事総括!#REF!
Name JVSB1会社名: [1]工事総括!#REF!
Name JVSB1会社名: [1]工事総括!#REF!
Name JVSB1会社名: [1]工事総括!#REF!
Name JVSB1会社名: [1]工事総括!#REF!
Name JVSB1会社名: [1]工事総括!#REF!
Name JVSB1会社名: [1]工事総括!#REF!
Name JVSB1会社名: [1]工事総括!#REF!
Name JVSB1比率: [1]工事総括!#REF!
Name JVSB1比率: [1]工事総括!#REF!
Name JVSB1比率: [1]工事総括!#REF!
Name JVSB1比率: [1]工事総括!#REF!
Name JVSB1比率: [1]工事総括!#REF!
Name JVSB1比率: [1]工事総括!#REF!
Name JVSB1比率: [1]工事総括!#REF!
Name JVSB2会社名: [1]工事総括!#REF!
Name JVSB2会社名: [1]工事総括!#REF!
Name JVSB2会社名: [1]工事総括!#REF!
Name JVSB2会社名: [1]工事総括!#REF!
Name JVSB2会社名: [1]工事総括!#REF!
Name JVSB2会社名: [1]工事総括!#REF!
Name JVSB2会社名: [1]工事総括!#REF!
Name JVSB2比率: [1]工事総括!#REF!
Name JVSB2比率: [1]工事総括!#REF!
Name JVSB2比率: [1]工事総括!#REF!
Name JVSB2比率: [1]工事総括!#REF!
Name JVSB2比率: [1]工事総括!#REF!
Name JVSB2比率: [1]工事総括!#REF!
Name JVSB2比率: [1]工事総括!#REF!
Name JVSB3会社名: [1]工事総括!#REF!
Name JVSB3会社名: [1]工事総括!#REF!
Name JVSB3会社名: [1]工事総括!#REF!
Name JVSB3会社名: [1]工事総括!#REF!
Name JVSB3会社名: [1]工事総括!#REF!
Name JVSB3会社名: [1]工事総括!#REF!
Name JVSB3会社名: [1]工事総括!#REF!
Name JVSB3比率: [1]工事総括!#REF!
Name JVSB3比率: [1]工事総括!#REF!
Name JVSB3比率: [1]工事総括!#REF!
Name JVSB3比率: [1]工事総括!#REF!
Name JVSB3比率: [1]工事総括!#REF!
Name JVSB3比率: [1]工事総括!#REF!
Name JVSB3比率: [1]工事総括!#REF!
Name JVSB4会社名: [1]工事総括!#REF!
Name JVSB4会社名: [1]工事総括!#REF!
Name JVSB4会社名: [1]工事総括!#REF!
Name JVSB4会社名: [1]工事総括!#REF!
Name JVSB4会社名: [1]工事総括!#REF!
Name JVSB4会社名: [1]工事総括!#REF!
Name JVSB4会社名: [1]工事総括!#REF!
Name JVSB4比率: [1]工事総括!#REF!
Name JVSB4比率: [1]工事総括!#REF!
Name JVSB4比率: [1]工事総括!#REF!
Name JVSB4比率: [1]工事総括!#REF!
Name JVSB4比率: [1]工事総括!#REF!
Name JVSB4比率: [1]工事総括!#REF!
Name JVSB4比率: [1]工事総括!#REF!
Name JVSB5会社名: [1]工事総括!#REF!
Name JVSB5会社名: [1]工事総括!#REF!
Name JVSB5会社名: [1]工事総括!#REF!

Sheet 表紙
AS1: 46001
B4: 世紀東急工業 株式会社 | Q4: 御中
B7: 【工 事 名】 | F7: 広島自動車道（特定更新等）烏帽子第三橋他1橋床版取替工事
B8: 【工 事 場 所】 | F8: 広島自動車道
B9: 【工 期】 | F9: 自 | P9: 至
B10: 【有 効 期 限】 | F10: 3ヵ月
B11: 【支払い条件】 | F11: 出来高現金払 現金100％
B12: 【産業廃棄物】 | F12: 産業廃棄物に関して当社に関りがあれば着工前に産廃契約を宜しくお願いします
B13: 【特記事項】 | F13: 別紙、工事見積確認書及び見積条件書による
B14: 【担 当 者】 | F14: 上原 拓
B16: 毎度、格別の御引立を賜り有難うございます。
B17: 御依頼を戴きました本件に付き、誠心誠意検討を加え御見積りいたしましたので
B18: 是非御下命戴けます様、お願い申し上げます。
B20: 小 計 金 額 | U20: =AL39 -> 1.0915e+08
B21: 消 費 税(10%) | U21: =U20*0.1 -> 10915000
B22: 合 計 金 額 | U22: =ROUND(U20*1.1,0) -> 120065000
B25: No. | D25: 名 称 | L25: 仕様・規格・寸法 | AC25: 数量 | AF25: 単位 | AH25: 単 価 | AL25: 金 額 | AS25: 備 考
B27: 1 | D27: 床版防水工 研掃 | L27: 内訳書別添え | AC27: 1 | AF27: 式 | AL27: =床版防水工!F23 -> 13300000
B29: 2 | D29: 床版補修工 WJ | L29: 内訳書別添え | AC29: 1 | AF29: 式 | AL29: ='床版補修 WJ'!F23 -> 48700000
B31: 3 | D31: 床版補修工 左官 | L31: 内訳書別添え | AC31: 1 | AF31: 式 | AL31: ='床版補修 リペア'!F24 -> 45000000
B33: 4 | D33: コンクリートはつり工 | L33: 内訳書別添え | AC33: 1 | AF33: 式 | AL33: =コンクリートハツリ工!F24 -> 2150000.2
BD38: NET | BJ38: 粗利 | BP38: 率
D39: 合 計 （税抜） | AL39: =SUM(AL26:AR38) -> 1.0915e+08 | BD39: ='[3]WJハツリ～床板補修～WJ研掃'!L25 -> #DIV/0! | BJ39: =AL39-BD39 -> #DIV/0! | BP39: =BD39/AL39 -> #DIV/0!
AS40: 決定 | AZ40: =BD39/AL40 -> #DIV/0!

Sheet 床版防水工
A1: 内 訳 明 細 書 1 | I1: 業 者 名
B2: 規 格 | C2: 数 量 | D2: 単 位 | E2: 単 価 | F2: 金 額 | G2: 備 考 | I2: 数 量 | J2: 単 位 | K2: 単 価 | L2: 金 額
A3: 床版防水工B1 研掃
A4: 床版防水工B1 | B4: 投射密度50㎏/ｍ2 巾1.0 | C4: 1515.9 | D4: m2 | E4: 700 | F4: =SUM(C4*E4) -> 1061130 | G4: ショットブラスト | I4: =SUM(F4/3) -> 353710
I5: =SUM(F5/3) -> 0 | L5: =SUM(I5*K5) -> 0
I6: =SUM(F6/3) -> 0
I7: =SUM(F7/3) -> 0 | L7: =SUM(I7*K7) -> 0
I8: =SUM(F8/3) -> 0
A9: 床版防水工B2 | I9: =SUM(F9/3) -> 0 | L9: =SUM(I9*K9) -> 0
A10: 床版防水工B2 | B10: 200～220Mpa | C10: 5588.5 | D10: m2 | E10: 1500 | F10: =SUM(C10*E10) -> 8382750 | G10: スピンジェット | I10: =SUM(C10/450) -> 12.418889 | J10: =SUM(F10/I10) -> 675000
I11: =SUM(F11/1) -> 0
I14: =SUM(F14/3) -> 0
I15: =SUM(F15/3) -> 0
A17: 直接工事費 | C17: 1 | D17: 式 | E17: =SUM(F4:F16) -> 9443880
A19: 機械回送費 | C19: 1 | D19: 式 | E19: =SUM(E17*16%) -> 1511020.8 | F19: =C19*E19 -> 1511020.8 | G19: 福岡～広島 往復
A20: 諸経費 | C20: 1 | D20: 式 | E20: =SUM(E17)*0.15 -> 1416582 | F20: =C20*E20 -> 1416582 | I20: =SUM(C4:C15) -> 7104.4 | K20: =SUM(L20/I20) -> 24.23667 | L20: 172187
A21: 端数調整 | C21: 1 | D21: 式 | E21: -13257 | F21: =C21*E21 -> -13257 | G21: 社会保険料率 ＝15.938％ | I21: =SUM(E21/20) -> -662.85
A22: 法定福利費（事業主負担分） | C22: 1 | D22: 式 | E22: =SUM(E17)*6.5% -> 613852.2 | F22: 941774
A23: 【小 計】 | C23: =SUM(C4:C15) -> 7104.4 | D23: m2 | E23: =SUM(F23/C23) -> 1872.0792 | F23: =SUM(F4:F22) -> 13300000 | I23: =SUM(F23/20) -> 664999.99 | L23: 14600000 | M23: =SUM(F23-L23) -> -1300000.2 | N23: =SUM(M23/L23) -> -0.08904111
A24: W J 歩 掛 明 細 書
A25: 名 称 | B25: 規 格 | C25: 数 量 | D25: 単 位 | E25: 単 価 | F25: 金 額 | G25: 備 考
A26: １．労務費
A27: 土木一般世話役 | B27: 令和6年度福岡県労務費単価 | C27: 1 | D27: 人 | E27: 29000 | F27: =SUM(E27*C27) -> 29000
A28: 特殊作業員 | B28: 令和6年度福岡県労務費単価 | C28: 3 | D28: 人 | E28: 25600 | F28: =SUM(E28*C28) -> 76800
A29: 特殊運転手 | B29: 令和6年度福岡県労務費単価 | C29: 2 | D29: 人 | E29: 24800 | F29: =SUM(E29*C29) -> 49600
A30: 普通作業員 | B30: 令和6年度福岡県労務費単価 | C30: 4 | D30: 人 | E30: 21900 | F30: =SUM(E30*C30) -> 87600 | L30: =SUM(L3:L27) -> 14772187
A31: 普通運転手 | B31: 令和6年度福岡県労務費単価 | C31: 2 | D31: 人 | E31: 22400 | F31: =SUM(E31*C31) -> 44800
A33: 2. 機械及び工具運転費
A34: 超高圧水発生装置 | B34: 245MPA・36L/min | C34: 1 | D34: 台 | E34: 200000 | F34: =E34*C34 -> 200000
A35: はつり装置運転費 | C35: 1 | D35: 台 | E35: 150000 | F35: =E35*C35 -> 150000
A36: 高性能吸引車 | B36: 10ｔ | C36: 2 | D36: 台 | E36: 191124 | F36: =SUM(C36*E36) -> 382248
A37: 散水車運転費 | B37: 4㎥ | C37: 2 | D37: 台
A38: 空気圧縮機 | C38: 1 | D38: 台 | E38: 8600 | F38: =E38*C38 -> 8600
A39: エアチッパー | C39: 0 | D39: 台 | E39: 2800 | F39: =E39*C39 -> 0
A40: 発動発電機 | B40: 40ｋVA | C40: 1 | D40: 台 | E40: 10392 | F40: =E40*C40 -> 10392
A41: 高圧洗浄機 | B41: エンジン駆動 | C41: 1 | D41: 台 | E41: 14664 | F41: =E41*C41 -> 14664
A42: トラック（クレーン装置付）運転費 | B42: 4ｔ 積2.9ｔ吊 | C42: 1 | D42: 台 | E42: 13500 | F42: =E42*C42 -> 13500
A43: トラック運転費 | B43: 2ｔ | C43: 1 | D43: 台 | E43: 9700 | F43: =E43*C43 -> 9700
A45: 3. 消耗材料費
A46: 超高圧ホース | B46: Φ8×20ｍ | C46: 10 | D46: 本 | E46: 450000 | F46: =E46*C46*0.025 -> 112500 | G46: 損耗率：0.025
...

Sheet 防水　条件書
A1: 施 工 条 件 書 1 | H1: 業 者 名
B2: 本見積りはコンクリート床版面を研掃工で施工する場合の見積もりです。 | H2: 数 量 | I2: 単 位 | J2: 単 価 | K2: 金 額
A3: 2 | B3: 施工条件によっては別途、協議または再見積もり致します。
A4: 3 | B4: 品質管理費を含んだ金額とします。 | K4: =SUM(H4*J4) -> 0
A5: 4 | B5: 細部、端部にて回転式研磨機を使用する場合があります。予めご了承ください。
A6: 5 | B6: 汚泥運搬、処分費は別途、清算願います。 | K6: =SUM(H6*J6) -> 0
A7: 6 | B7: 現地近隣に排水処理用仮設プラントの仮設場所、及び工事車両の駐車場所を提供願います。
A8: 7 | B8: 本見積もりには試験施工費、産廃処分費、道路規制費は一切含まれておりません。 | K8: =SUM(H8*J8) -> 0
A9: 8 | B9: ご精算は実施工数量にてお願い致します。
A10: 9 | B10: 施工範囲内において障害物等撤去移設され連続作業可能な状態での作業とします。 | K10: =SUM(H10*J10) -> 0
A11: 10 | B11: 項目にないものは別途協議願います。
A12: 11 | B12: 資材置場、作業用車両駐車場の無償支給お願いします。 | K12: =SUM(H12*J12) -> 0
K23: =SUM(K3:K20) -> 0
H25: 数量 | I25: 単位 | J25: 単 価 | K25: 金 額
K46: =K23+K39 -> 0

Sheet 床版補修　WJ
A1: 内 訳 明 細 書 2 | I1: 業 者 名
B2: 規 格 | C2: 数 量 | D2: 単 位 | E2: 単 価 | F2: 金 額 | G2: 備 考 | I2: 数 量 | J2: 単 位 | K2: 単 価 | L2: 金 額
A3: 床版はつり工
K4: 20 | L4: =SUM(I4*K4) -> 0 | M4: 原価計 | N4: 返済ｍ3 | O4: ポンプ | P4: 労務 | Q4: 車両費 | R4: 吸引車
A5: 床版はつりA 鳥帽子第三橋（上り） | B5: t=8㎝ フェーザーエッジ対策 | C5: 31896 | D5: L | E5: 900 | F5: =SUM(C5*E5) -> 28706400 | G5: WJロボ | I5: =C5 -> 31896 | K5: =SUM(E5*0.8) -> 720 | L5: =SUM(I5*K5) -> 22965120 | M5: =SUM(N5:T5) -> 1075000 | N5: 200000 | O5: 200000 | P5: 250000 | Q5: 125000 | R5: 300000
A6: 床版はつりB 鳥帽子第三橋（上り） | B6: t=5㎝ フェーザーエッジ対策 | C6: 4860 | D6: L | E6: 500 | F6: =SUM(C6*E6) -> 2430000 | G6: 打撃ハツリ | I6: =C6 -> 4860 | K6: =SUM(E6*0.8) -> 400 | L6: =SUM(I6*K6) -> 1944000
A7: コンクリートハツリ 雲田橋（上り） | B7: t=15㎝ | C7: 655.5 | D7: L | E7: 2500 | F7: =SUM(C7*E7) -> 1638750 | G7: WJ人力(ハンドガン) | I7: =C7 -> 655.5 | K7: =SUM(E7*0.8) -> 2000 | L7: =SUM(I7*K7) -> 1311000
I8: =C8 -> 0 | K8: =SUM(E8*0.8) -> 0 | L8: =SUM(I8*K8) -> 0
A9: 吸引業者の汚泥運搬・処分費は含まれておりません。 | I9: =C9 -> 0 | K9: =SUM(E9*0.8) -> 0 | L9: =SUM(I9*K9) -> 0
I10: =C10 -> 0 | K10: =SUM(E10*0.8) -> 0 | L10: =SUM(I10*K10) -> 0
A17: 直接工事費 | C17: 1 | D17: 式 | E17: =SUM(F5:F16) -> 32775150 | I17: 1 | J17: 式 | K17: =SUM(N5:N10) -> 200000
A18: 機械回送費 | B18: 大型車2台(吸引車) 中型3台(WJ車) 散水車2台 作業車1台 | C18: 1 | D18: 式 | E18: =SUM(E17*16%) -> 5244024 | F18: =C18*E18 -> 5244024 | G18: 福岡～広島 往復 | I18: =SUM(F18/E17) -> 0.16
I19: 35 | J19: 往復 | K19: =SUM(E19*0.8) -> 0 | L19: =I19*K19 -> 0
A20: 諸経費 | C20: 1 | D20: 式 | E20: =SUM(E17)*0.15 -> 4916272.5 | F20: =C20*E20 -> 4916272.5 | I20: 1 | J20: 式 | K20: =SUM(E20*0.8) -> 3933018 | L20: =I20*K20 -> 3933018
A21: 端数調整 | C21: 1 | D21: 式 | E21: -33454 | F21: =C21*E21 -> -33454 | G21: 社会保険料率 ＝15.938％ | I21: 1 | J21: 式 | K21: =SUM(E21*0.8) -> -26763.2 | L21: =I21*K21 -> -26763.2
A22: 法定福利費（事業主負担分） | C22: 1 | D22: 式 | E22: =SUM(E17)*6.5% -> 2130384.8 | F22: 5798007 | I22: 1 | J22: 式 | K22: =SUM(E22*0.8) -> 1704307.8 | L22: =I22*K22 -> 1704307.8
A23: 【小 計】 | F23: =SUM(F5:F22) -> 48700000 | L23: =SUM(L3:L22) -> 31830683 | M23: =SUM(F23-L23) -> 16869317 | N23: =SUM(M23/F23) -> 0.34639255
A24: W J 歩 掛 明 細 書
A25: 名 称 | B25: 規 格 | C25: 数 量 | D25: 単 位 | E25: 単 価 | F25: 金 額 | G25: 備 考
A26: １．労務費
A27: 土木一般世話役 | C27: 1 | D27: 人 | E27: 25200 | F27: =SUM(E27*C27) -> 25200
A28: 特殊作業員 | C28: 3 | D28: 人 | E28: 22100 | F28: =SUM(E28*C28) -> 66300
A29: 特殊運転手 | C29: 4 | D29: 人 | E29: 22700 | F29: =SUM(E29*C29) -> 90800
A30: 普通作業員 | C30: 4 | D30: 人 | E30: 19200 | F30: =SUM(E30*C30) -> 76800
A31: 普通運転手 | C31: 4 | D31: 人 | E31: 20300 | F31: =SUM(E31*C31) -> 81200
A33: 2. 機械及び工具運転費
A34: 超高圧水発生装置 | B34: 245MPA・36L/min | C34: 2 | D34: 台 | E34: 175000 | F34: =E34*C34 -> 350000
A35: はつり装置運転費 | B35: 245MPA・90L/min | C35: 1 | D35: 台 | E35: 190000 | F35: =E35*C35 -> 190000
A36: 高性能吸引車 | B36: 10ｔ | C36: 2 | D36: 台 | E36: 180000 | F36: =SUM(C36*E36) -> 360000
A37: 散水車運転費 | B37: 4㎥ | C37: 2 | D37: 台
A38: 空気圧縮機 | C38: 1 | D38: 台 | E38: 8600 | F38: =E38*C38 -> 8600
A39: エアチッパー | C39: 3 | D39: 台 | E39: 2800 | F39: =E39*C39 -> 8400
A40: 発動発電機 | B40: 40ｋVA | C40: 1 | D40: 台 | E40: 10392 | F40: =E40*C40 -> 10392
A41: 高圧洗浄機 | B41: エンジン駆動 | C41: 1 | D41: 台 | E41: 14664 | F41: =E41*C41 -> 14664
A42: トラック（クレーン装置付）運転費 | B42: 4ｔ 積2.9ｔ吊 | C42: 1 | D42: 台 | E42: 13500 | F42: =E42*C42 -> 13500
A43: トラック運転費 | B43: 2ｔ | C43: 1 | D43: 台 | E43: 9700 | F43: =E43*C43 -> 9700
A45: 3. 消耗材料費
A46: 超高圧ホース | B46: Φ8×20ｍ | C46: 10 | D46: 本 | E46: 450000 | F46: =E46*C46*0.025 -> 112500 | G46: 損耗率：0.025
A47: 超高圧ノズル | B47: 1ユニット 2個ノズル使用 | C47: 1 | D47: セット | E47: 50000 | F47: =E47*C47*0.25 -> 12500 | G47: 損耗率：0.25
A48: はつり装置廻り | B48: 単管・他 | C48: 1 | D48: 式 | E48: 25000 | F48: =E48*C48 -> 25000
...

Sheet 床版補修　条件書
A1: 施 工 条 件 書 2 | H1: 業 者 名
B2: 本見積りはコンクリート床版面をWJロボットはつり工法で施工する場合の見積もりです。 | H2: 数 量 | I2: 単 位 | J2: 単 価 | K2: 金 額
A3: 2 | B3: 施工条件によっては別途、協議または再見積もり致します。
A4: 3 | B4: 施工に必要な給水源の支給（清水）をお願い致します。 | K4: =SUM(H4*J4) -> 0
A5: 4 | B5: 本見積もりには試験施工費、産廃処分費、道路規制費は一切含まれておりません。
A6: 5 | B6: ご精算は実施工数量にてお願い致します。 | K6: =SUM(H6*J6) -> 0
A7: 6 | B7: 現地近隣に排水処理用仮設プラントの仮設場所、及び工事車両の駐車場所を提供願います。
A8: 7 | B8: 本見積もりには試験施工費、産廃処分費、道路規制費は一切含まれておりません。 | K8: =SUM(H8*J8) -> 0
A9: 8 | B9: ご精算は実施工数量にてお願い致します。
A10: 9 | B10: 飛散養生等の安全対策費は含まれております。 | K10: =SUM(H10*J10) -> 0
A11: 10 | B11: 吸引業者の汚泥運搬・処分費は含まれておりません。直接元請様から吸引業者へお支払いお願いします。
A12: 11 | B12: 散水車の費用は含まれております。 | K12: =SUM(H12*J12) -> 0
A13: 12 | B13: はつりガラの汚泥を一旦、濁水処理施設にの費用は含みませんが準備等は無償でご協力いたします。
K23: =SUM(K3:K20) -> 0
H25: 数量 | I25: 単位 | J25: 単 価 | K25: 金 額
K46: =K23+K39 -> 0

Sheet 床版補修　リペア
A1: 内 訳 明 細 書 3 | I1: 業 者 名
B2: 規 格 | C2: 数 量 | D2: 単 位 | E2: 単 価 | F2: 金 額 | G2: 備 考 | I2: 数 量 | J2: 単 位 | K2: 単 価 | L2: 金 額
A3: 床版補修工(左官)
A4: 床版はつりA 鳥帽子第三橋（上り） | B4: PDジェットスラブ（13）ミニパック | C4: 31896 | D4: L | E4: 750 | F4: =SUM(C4*E4) -> 23922000
A5: 床版はつりB 鳥帽子第三橋（上り） | B5: PDジェットスラブ（13）ミニパック | C5: 4860 | D5: L | E5: 750 | F5: =SUM(C5*E5) -> 3645000
A18: 直接工事費 | C18: 1 | D18: 式 | E18: =SUM(F4:F17) -> 27567000 | I18: 1 | J18: 式 | K18: =SUM(N5:N11) -> 0
A19: 機械回送費 | B19: 中型2台(材料・ミキサー) 作業車1台 | C19: 1 | D19: 式 | E19: =SUM(E18*16%) -> 4410720 | F19: =C19*E19 -> 4410720 | G19: 福岡～広島 往復
I20: 2 | J20: 往復 | K20: 80000 | L20: =I20*K20 -> 160000 | N20: =SUM(L20*0.7) -> 112000
A21: 諸経費 | C21: 1 | D21: 式 | E21: =SUM(E18)*0.15 -> 4135050 | F21: 9122738 | I21: 1 | J21: 式 | K21: =SUM(K18)*0.1 -> 0 | L21: =I21*K21 -> 0 | N21: =SUM(L21*0.7) -> 0
A22: 端数調整 | C22: 1 | D22: 式 | E22: -53644 | F22: =C22*E22 -> -53644 | G22: 社会保険料率 ＝15.938％ | I22: 1 | J22: 式 | L22: =I22*K22 -> 0 | N22: =SUM(L22*0.7) -> 0
A23: 法定福利費（事業主負担分） | C23: 1 | D23: 式 | E23: =SUM(E18)*6.5% -> 1791855 | F23: 3953186 | I23: 1 | J23: 式 | K23: =SUM(K18)*5% -> 0 | L23: =I23*K23 -> 0 | N23: =SUM(L23*0.7) -> 0
A24: 【小 計】 | C24: =SUM(C4:C17) -> 36756 | D24: ｍ3 | E24: =SUM(F24/C24) -> 1224.2899 | F24: =SUM(F3:F23) -> 45000000 | L24: =SUM(L3:L23) -> 160000 | N24: =SUM(N3:N23) -> 112000
A25: W J 歩 掛 明 細 書 | L25: =SUM(F24-L24) -> 44840000 | M25: =SUM(L25/F24) -> 0.99644444 | N25: =SUM(L24-N24) -> 48000 | O25: =SUM(N25/L24) -> 0.3 | P25: =SUM(L25+N25)/F24 -> 0.99751111
A26: 名 称 | B26: 規 格 | C26: 数 量 | D26: 単 位 | E26: 単 価 | F26: 金 額 | G26: 備 考
A27: １．労務費
A28: 土木一般世話役 | C28: 1 | D28: 人 | E28: 25200 | F28: =SUM(E28*C28) -> 25200
A29: 特殊作業員 | C29: 3 | D29: 人 | E29: 22100 | F29: =SUM(E29*C29) -> 66300
A30: 特殊運転手 | C30: 4 | D30: 人 | E30: 22700 | F30: =SUM(E30*C30) -> 90800
A31: 普通作業員 | C31: 4 | D31: 人 | E31: 19200 | F31: =SUM(E31*C31) -> 76800
A32: 普通運転手 | C32: 4 | D32: 人 | E32: 20300 | F32: =SUM(E32*C32) -> 81200
A34: 2. 機械及び工具運転費
A35: 超高圧水発生装置 | B35: 245MPA・36L/min | C35: 2 | D35: 台 | E35: 175000 | F35: =E35*C35 -> 350000
A36: はつり装置運転費 | B36: 245MPA・90L/min | C36: 1 | D36: 台 | E36: 190000 | F36: =E36*C36 -> 190000
A37: 高性能吸引車 | B37: 10ｔ | C37: 2 | D37: 台 | E37: 180000 | F37: =SUM(C37*E37) -> 360000
A38: 散水車運転費 | B38: 4㎥ | C38: 2 | D38: 台
A39: 空気圧縮機 | C39: 1 | D39: 台 | E39: 8600 | F39: =E39*C39 -> 8600
A40: エアチッパー | C40: 3 | D40: 台 | E40: 2800 | F40: =E40*C40 -> 8400
A41: 発動発電機 | B41: 40ｋVA | C41: 1 | D41: 台 | E41: 10392 | F41: =E41*C41 -> 10392
A42: 高圧洗浄機 | B42: エンジン駆動 | C42: 1 | D42: 台 | E42: 14664 | F42: =E42*C42 -> 14664
A43: トラック（クレーン装置付）運転費 | B43: 4ｔ 積2.9ｔ吊 | C43: 1 | D43: 台 | E43: 13500 | F43: =E43*C43 -> 13500
A44: トラック運転費 | B44: 2ｔ | C44: 1 | D44: 台 | E44: 9700 | F44: =E44*C44 -> 9700
A46: 3. 消耗材料費
A47: 超高圧ホース | B47: Φ8×20ｍ | C47: 10 | D47: 本 | E47: 450000 | F47: =E47*C47*0.025 -> 112500 | G47: 損耗率：0.025
A48: 超高圧ノズル | B48: 1ユニット 2個ノズル使用 | C48: 1 | D48: セット | E48: 50000 | F48: =E48*C48*0.25 -> 12500 | G48: 損耗率：0.25
A49: はつり装置廻り | B49: 単管・他 | C49: 1 | D49: 式 | E49: 25000 | F49: =E49*C49 -> 25000
A50: 端数調整 | C50: 1 | D50: 式 | E50: -5556 | F50: =E50*C50 -> -5556
A51: 【小 計】 | F51: =SUM(F27:F50) -> 1450000
A52: ｍ3単価 | C52: 0.7 | D52: ｍ3/日 | E52: =SUM(F51) -> 1450000 | F52: =SUM(C52*E52) -> 1015000

Sheet WJ床版補修　条件書 
A1: 施 工 条 件 書 3
B2: 本見積りは床版上面における断面修復を左官工法で施工する場合の見積もりです。 | I2: 単 位 | J2: 単 価 | K2: 金 額
A3: 2 | B3: 施工条件によっては別途、協議または再見積もり致します。
A4: 3 | B4: 施工に必要な給水源の支給（清水）をお願い致します。 | K4: =SUM(#REF!*J4) -> #REF!
A5: 4 | B5: 本見積もりには試験施工費、産廃処分費、道路規制費は一切含まれておりません。
A6: 5 | B6: ご精算は実施工数量にてお願い致します。 | K6: =SUM(#REF!*J6) -> #REF!
A7: 6 | B7: 現地近隣に排水処理用仮設プラントの仮設場所、及び工事車両の駐車場所を提供願います。
A8: 7 | B8: 本見積もりには試験施工費、産廃処分費、道路規制費は一切含まれておりません。 | K8: =SUM(#REF!*J8) -> #REF!
A9: 8 | B9: ボンド塗布する際の飛散養生等の安全対策費は含まれております。
A10: 9 | B10: 使用するコンクリートミキサーは【パワーミキサーPTM-10強力型】でのお見積りです。(予備機含む2台体制で施工いたします。) | K10: =SUM(#REF!*J10) -> #REF!
A11: 10 | B11: 「PDジェット・スラブ」はNEXCO構造物施工管理要領 床版上面における断面修復材規格適合品です。
A12: 11 | B12: 「PDジェットスラブ（13）ベースパック：練上り約150L/set、ミニパック：練上り約21L/set」 | K12: =SUM(#REF!*J12) -> #REF!
A13: 12 | B13: 「PDプライマー」「PDボンド」共にNEXCO構造物施工管理要領 鉄筋防錆材規格適合品です。
A14: 13 | B14: WJ打の場台はPDプライマーの塗布は必要ありませんが、手研の場合はPDプライマーの塗布が必要です。
A15: 14 | B15: （WJ研の場合：PDプライマー無し＋PDボンド1.2kg/m2、手研の場合はプライマー0.5kg/m2＋PDボンド0.8kg/m2）
A16: 15 | B16: 遅延剤添加量は気温により添加量を変化致します。ベースパック（60〜550g/セット）、ミニパック（8〜70g/セット）
A17: 16 | B17: コンクリート試験費は含まれておりません。(ポータブル圧縮試験機の準備はございますので別途見積)
K23: =SUM(K3:K20) -> #REF!
I25: 単位 | J25: 単 価 | K25: 金 額
K46: =K23+K39 -> #REF!

Sheet コンクリートハツリ工
A1: 内 訳 明 細 書 4 | I1: 業 者 名
B2: 規 格 | C2: 数 量 | D2: 単 位 | E2: 単 価 | F2: 金 額 | G2: 備 考 | I2: 数 量 | J2: 単 位 | K2: 単 価 | L2: 金 額
A4: コンクリートハツリ 雲田橋（上り） | B4: t=15㎝ | C4: 655.5 | D4: L | E4: 2500 | F4: =SUM(C4*E4) -> 1638750 | G4: WJ人力(ハンドガン) | I4: =SUM(C4) -> 655.5 | K4: =SUM(E4*0.75) -> 1875 | L4: =SUM(I4*K4) -> 1229062.5 | M4: =SUM(F4-L4) -> 409687.5 | N4: =SUM(M4/F4) -> 0.25
I5: =SUM(C5) -> 0 | K5: =SUM(E5*0.75) -> 0 | L5: =SUM(I5*K5) -> 0 | M5: =SUM(F5-L5) -> 0 | N5: =SUM(M5/F5) -> #DIV/0!
I6: =SUM(C6) -> 0 | K6: =SUM(E6*0.75) -> 0 | L6: =SUM(I6*K6) -> 0 | M6: =SUM(F6-L6) -> 0 | N6: =SUM(M6/F6) -> #DIV/0!
I7: =SUM(C7) -> 0 | K7: =SUM(E7*0.75) -> 0 | L7: =SUM(I7*K7) -> 0 | M7: =SUM(F7-L7) -> 0 | N7: =SUM(M7/F7) -> #DIV/0!
A18: 直接工事費 | C18: 1 | D18: 式 | E18: =SUM(F4:F17) -> 1638750 | I18: 1 | J18: 式 | K18: =SUM(L4:L10) -> 1229062.5
A19: 機械回送費 | B19: ポンプ車 散水車 | C19: 1 | D19: 式 | E19: =SUM(F4:F7)*10% -> 163875 | F19: =C19*E19 -> 163875 | G19: 福岡～広島 往復 | I19: =SUM(C19) -> 1 | K19: =SUM(E19*0.75) -> 122906.25 | L19: =SUM(I19*K19) -> 122906.25 | M19: =SUM(F19-L19) -> 40968.75
K20: =SUM(F20) -> 0
A21: 諸経費 | C21: 1 | D21: 式 | E21: =SUM(E18)*0.15 -> 245812.5 | F21: =C21*E21 -> 245812.5 | I21: =SUM(C21) -> 1 | K21: =SUM(E21*0.75) -> 184359.38 | L21: =SUM(I21*K21) -> 184359.38 | M21: =SUM(F21-L21) -> 61453.125
A22: 端数調整 | C22: 1 | D22: 式 | E22: -4956 | F22: =C22*E22 -> -4956 | G22: 社会保険料率 ＝15.938％ | I22: =SUM(C22) -> 1 | K22: =SUM(E22*0.75) -> -3717 | L22: =SUM(I22*K22) -> -3717
A23: 法定福利費（事業主負担分） | C23: 1 | D23: 式 | E23: =SUM(E18)*6.5% -> 106518.75 | F23: =C23*E23 -> 106518.75 | I23: =SUM(C23) -> 1 | K23: =SUM(E23*0.75) -> 79889.062 | L23: =SUM(I23*K23) -> 79889.062 | M23: =SUM(F23-L23) -> 26629.688
A24: 【小 計】 | C24: =SUM(C4:C7) -> 655.5 | D24: ｍ3 | E24: =SUM(F24/C24) -> 3279.9394 | F24: =SUM(F3:F23) -> 2150000.2 | I24: =SUM(I4:I7) -> 655.5 | J24: ｍ3 | K24: =SUM(L24/I24) -> 2459.9545 | L24: =SUM(L3:L23) -> 1612500.2 | M24: =SUM(F24-L24) -> 537500.06 | N24: =SUM(M24/F24) -> 0.25
A25: W J 歩 掛 明 細 書
A26: 名 称 | B26: 規 格 | C26: 数 量 | D26: 単 位 | E26: 単 価 | F26: 金 額 | G26: 備 考
A27: １．労務費
A28: 土木一般世話役 | C28: 1 | D28: 人 | E28: 25200 | F28: =SUM(E28*C28) -> 25200
A29: 特殊作業員 | C29: 3 | D29: 人 | E29: 22100 | F29: =SUM(E29*C29) -> 66300
A30: 特殊運転手 | C30: 4 | D30: 人 | E30: 22700 | F30: =SUM(E30*C30) -> 90800
A31: 普通作業員 | C31: 4 | D31: 人 | E31: 19200 | F31: =SUM(E31*C31) -> 76800
A32: 普通運転手 | C32: 4 | D32: 人 | E32: 20300 | F32: =SUM(E32*C32) -> 81200
A34: 2. 機械及び工具運転費
A35: 超高圧水発生装置 | B35: 245MPA・36L/min | C35: 2 | D35: 台 | E35: 175000 | F35: =E35*C35 -> 350000
A36: はつり装置運転費 | B36: 245MPA・90L/min | C36: 1 | D36: 台 | E36: 190000 | F36: =E36*C36 -> 190000
A37: 高性能吸引車 | B37: 10ｔ | C37: 2 | D37: 台 | E37: 180000 | F37: =SUM(C37*E37) -> 360000
A38: 散水車運転費 | B38: 4㎥ | C38: 2 | D38: 台
A39: 空気圧縮機 | C39: 1 | D39: 台 | E39: 8600 | F39: =E39*C39 -> 8600
A40: エアチッパー | C40: 3 | D40: 台 | E40: 2800 | F40: =E40*C40 -> 8400
A41: 発動発電機 | B41: 40ｋVA | C41: 1 | D41: 台 | E41: 10392 | F41: =E41*C41 -> 10392
A42: 高圧洗浄機 | B42: エンジン駆動 | C42: 1 | D42: 台 | E42: 14664 | F42: =E42*C42 -> 14664
A43: トラック（クレーン装置付）運転費 | B43: 4ｔ 積2.9ｔ吊 | C43: 1 | D43: 台 | E43: 13500 | F43: =E43*C43 -> 13500
A44: トラック運転費 | B44: 2ｔ | C44: 1 | D44: 台 | E44: 9700 | F44: =E44*C44 -> 9700
A46: 3. 消耗材料費
A47: 超高圧ホース | B47: Φ8×20ｍ | C47: 10 | D47: 本 | E47: 450000 | F47: =E47*C47*0.025 -> 112500 | G47: 損耗率：0.025
A48: 超高圧ノズル | B48: 1ユニット 2個ノズル使用 | C48: 1 | D48: セット | E48: 50000 | F48: =E48*C48*0.25 -> 12500 | G48: 損耗率：0.25
A49: はつり装置廻り | B49: 単管・他 | C49: 1 | D49: 式 | E49: 25000 | F49: =E49*C49 -> 25000
A50: 端数調整 | C50: 1 | D50: 式 | E50: -5556 | F50: =E50*C50 -> -5556
A51: 【小 計】 | F51: =SUM(F27:F50) -> 1450000
A52: ｍ3単価 | C52: 0.7 | D52: ｍ3/日 | E52: =SUM(F51) -> 1450000 | F52: =SUM(C52*E52) -> 1015000

Sheet ハンドガン　条件書 
A1: 施 工 条 件 書 4 | H1: 業 者 名
B2: 本見積りはコンクリート床版面をWJはつり工法で施工する場合の見積もりです。 | H2: 数 量 | I2: 単 位 | J2: 単 価 | K2: 金 額
A3: 2 | B3: 本見積りは実施工時間が8時間確保できる条件に対する御見積りです、夜間、規制等で作業時間が限られる場合は割増となりますのでご了承願います。
A4: 3 | B4: 施工に必要な給水源の支給（清水）をお願い致します。 | K4: =SUM(H4*J4) -> 0
A5: 4 | B5: 本見積もりには試験施工費、産廃処分費、道路規制費は一切含まれておりません。
A6: 5 | B6: ご精算は実施工数量にてお願い致します。 | K6: =SUM(H6*J6) -> 0
A7: 6 | B7: 工事車両及び資機材は、ヤード内における条件での御見積りとなっております 規制等で移動がある場合は、車両置き場の確保をお願い致します。
A8: 7 | B8: 本見積もりには試験施工費、産廃処分費、道路規制費は一切含まれておりません。 | K8: =SUM(H8*J8) -> 0
A9: 8 | B9: ご精算は実施工数量にてお願い致します。
A10: 9 | B10: はつりガラ、養生等の廃棄物は同現場内の集積場所まで運搬します、処理場への収集運搬及び処分費は含んでおりません。 | K10: =SUM(H10*J10) -> 0
A11: 10 | B11: 現場近隣に排水処理に必要な排水タンク3基（10ｍ3）水中ポンプ（5～10台）撹拌用水中ポンプ（3台）仮設電源のご支給願います。
A12: 11 | B12: はつり処理面にはフェザーエッジ対策として既設コンクリートとの境界に1ｃｍ程度のカッター処理を行います、施工範囲の墨出し防錆処理等は含まれておりません。 | K12: =SUM(H12*J12) -> 0
A13: 12 | B13: 施工排水は水槽に貯留後、PH、濁度調整を行い上澄み水は現調放流とさせて頂きます、尚汚泥等の処分費は含んでおりません。
A14: 13 | B14: WJ表面処理の対象物はコンクリート素地としております。塗膜等ありましたら再見積りとさせていただきます。
A15: 14 | B15: WJ表面処理の治具が入らない等処理ができない場合は、ディスクサンダーやワイヤブラシでのケレンとなりますのでご了承願います。
A16: 15 | B16: 仮設足場（移動式足場）は含まれておりません、ご支給願います。
A17: 16 | B17: 数量、条件等に変更が生じた場合はお互いの協議の上変更等の対応をお願いします。
K23: =SUM(K3:K20) -> 0
H25: 数量 | I25: 単位 | J25: 単 価 | K25: 金 額
K46: =K23+K39 -> 0

Sheet 舗装関連　表紙
AS1: 45974
B4: 世紀東急工業 株式会社 | Q4: 御中
B7: 【工 事 名】 | F7: 広島自動車道（特定更新等）烏帽子第三橋他1橋床版取替工事 | BA7: =F7 -> 広島自動車道（特定更新等）烏帽子第三橋他1橋床版取替工事
B8: 【工 事 場 所】 | F8: 広島自動車道
B9: 【工 期】 | F9: 自 | P9: 至
B10: 【有 効 期 限】 | F10: 3ヵ月
B11: 【支払い条件】 | F11: 出来高現金払 現金100％
B12: 【産業廃棄物】 | F12: 産業廃棄物に関して当社に関りがあれば着工前に産廃契約を宜しくお願いします
B13: 【特記事項】 | F13: 別紙、工事見積確認書及び見積条件書による
B14: 【担 当 者】 | F14: 渡辺 基弥
B16: 毎度、格別の御引立を賜り有難うございます。
B17: 御依頼を戴きました本件に付き、誠心誠意検討を加え御見積りいたしましたので
B18: 是非御下命戴けます様、お願い申し上げます。
AG19: 単価見積
B20: 小 計 金 額 | U20: =AL39 -> 4583001
B21: 消 費 税(10%) | U21: =U20*0.1 -> 458300.1
B22: 合 計 金 額 | U22: =ROUND(U20*1.1,0) -> 5041301
B25: No. | D25: 名 称 | L25: 仕様・規格・寸法 | AC25: 数量 | AF25: 単位 | AH25: 単 価 | AL25: 金 額 | AS25: 備 考
D26: 舗装工 | L26: 内訳書別添え
B27: 1 | D27: 切削オーバーレイ工(土工部) | L27: 昼間施工 8時～17時 | AC27: 1 | AF27: 日/式 | AH27: ='舗装関連 内訳書'!F19 -> 570000.4 | AL27: =SUM(AC27*AH27) -> 570000.4
B28: 2 | D28: 切削オーバーレイ工(土工部) | L28: 夜昼施工 19時～翌9時 | AC28: 1 | AF28: 日/式 | AH28: ='舗装関連 内訳書'!F38 -> 697000.04 | AL28: =SUM(AC28*AH28) -> 697000.04
B29: 3 | D29: 切削オーバーレイ工(土工部) | L29: 夜間施工 19時～翌5時 | AC29: 1 | AF29: 日/式 | AH29: ='舗装関連 内訳書'!F58 -> 670000.29 | AL29: =SUM(AC29*AH29) -> 670000.29
B30: 4 | D30: 切削オーバーレイ工(橋梁部) | L30: 撤去のみ 夜間施工 19時～翌1時 | AC30: 1 | AF30: 日/式 | AH30: ='舗装関連 内訳書'!F79 -> 401999.99 | AL30: =SUM(AC30*AH30) -> 401999.99
B31: 5 | D31: 切削オーバーレイ工(橋梁部) | L31: 舗装のみ 昼間施工 9時～12時 | AC31: 1 | AF31: 日/式 | AH31: ='舗装関連 内訳書'!F99 -> 510000.4 | AL31: =SUM(AC31*AH31) -> 510000.4
B32: 6 | D32: 切削オーバーレイ工(橋梁部) | L32: 夜間施工 19時～翌5時 | AC32: 1 | AF32: 日/式 | AH32: ='舗装関連 内訳書'!F119 -> 684000.29 | AL32: =SUM(AC32*AH32) -> 684000.29
B33: 7 | D33: 打換工(橋梁部) | L33: 夜間施工 | AC33: 1 | AF33: 日/式 | AH33: ='舗装関連 内訳書'!F140 -> 399000.11 | AL33: =SUM(AC33*AH33) -> 399000.11
B34: 8 | D34: 打換工(橋梁部) | L34: 夜間施工 地覆部縁石撤去舗装 19時～翌5時 | AC34: 1 | AF34: 日/式 | AH34: ='舗装関連 内訳書'!F159 -> 372000.36 | AL34: =SUM(AC34*AH34) -> 372000.36
B35: 9 | D35: 事前調査 夜間 | L35: 夜間 19時～5時 | AC35: 1 | AF35: 日/式 | AH35: ='舗装関連 内訳書'!F178 -> 158999.56 | AL35: =SUM(AC35*AH35) -> 158999.56
B36: 10 | D36: 事前調査 昼間 | L36: 昼間 8時～17時 | AC36: 1 | AF36: 日/式 | AH36: ='舗装関連 内訳書'!F197 -> 119999.6 | AL36: =SUM(AC36*AH36) -> 119999.6
BD38: NET | BJ38: 粗利 | BP38: 率
D39: 合 計 （税抜） | AL39: =SUM(AL26:AR38) -> 4583001 | BD39: ='[3]WJハツリ～床板補修～WJ研掃'!L25 -> #DIV/0! | BJ39: =AL39-BD39 -> #DIV/0! | BP39: =BD39/AL39 -> #DIV/0!
AS40: 決定 | AZ40: =BD39/AL40 -> #DIV/0!

Sheet 舗装関連　内訳書
A1: 内 訳 明 細 書 1 | I1: 業 者 名
B2: 規 格 | C2: 数 量 | D2: 単 位 | E2: 単 価 | F2: 金 額 | G2: 備 考 | I2: 数 量 | J2: 単 位 | K2: 単 価 | L2: 金 額
A3: 1. 切削オーバーレイ工(土工部) | B3: 昼間施工 8：00～17：00 | G3: 1日日当たり
A4: 特殊作業員 | B4: 職長1 6.0AF２ MR1 TR1 | C4: 5 | D4: 人工 | E4: 26700 | F4: =SUM(C4*E4) -> 133500 | G4: 機械オペ | L4: =SUM(I4*K4) -> 0
A5: 普通作業員 | B5: スコップ2 レーキ2 誘導員1 監視員1 | C5: 6 | D5: 人工 | E5: 23600 | F5: =SUM(C5*E5) -> 141600
A6: 小物機械費 | B6: 清掃 はつり 転圧機械 コアマシーン | C6: 1 | D6: 日/式 | E6: 33000 | F6: =SUM(C6*E6) -> 33000 | L6: =SUM(I6*K6) -> 0
A7: 車両費 | B7: Wキャブ 3ｔダンプ 連絡車2 | C7: 1 | D7: 日/式 | E7: 20000 | F7: =SUM(C7*E7) -> 20000
A8: 交通費 | B8: 高速代 燃料費 | C8: 1 | D8: 日/式 | E8: 22000 | F8: =SUM(C8*E8) -> 22000 | L8: =SUM(I8*K8) -> 0
A9: 重機機械費 | B9: 6.0AF MR TR 0.15BH AFセンサー | C9: 1 | D9: 日/式 | E9: 95000 | F9: =SUM(C9*E9) -> 95000 | G9: 稼働月１０日以上
A10: 重機燃料費 | B10: 軽油 | C10: 1 | D10: 日/式 | E10: 15000 | F10: =SUM(C10*E10) -> 15000 | L10: =SUM(I10*K10) -> 0
A11: 残業 | B11: 作業時間8ｈを超えた場合 | C11: 1 | D11: ｈ | E11: 3400 | G11: 別途請求
A15: 労働災害防止対策費 | C15: 1 | D15: 式 | E15: =SUM(F4:F11)*0.004 -> 1840.4 | F15: =SUM(C15*E15) -> 1840.4
A16: 諸経費 | C16: 1 | D16: 式 | E16: =SUM(F4:F11)*0.15 -> 69015 | F16: =SUM(C16*E16) -> 69015 | I16: =SUM(F4:F13) -> 460100
A17: 端数調整 | F17: -2220 | G17: 社会保険料率 ＝15.938％ | I17: =SUM(E18/I16) -> 0.089687025
A18: 法定福利費 | C18: 1 | D18: 式 | E18: =SUM(F4:F5)*0.15 -> 41265 | F18: =SUM(C18*E18) -> 41265
A19: 1. 【合計】 | F19: =SUM(F4:F18) -> 570000.4 | L19: =SUM(L3:L16) -> 0
A20: 内 訳 明 細 書 2
A21: 名 称 | B21: 規 格 | C21: 数 量 | D21: 単 位 | E21: 単 価 | F21: 金 額 | G21: 備 考 | I21: 数量 | J21: 単位 | K21: 単 価 | L21: 金 額
A22: 2. 切削オーバーレイ工(土工部) | B22: 夜昼施工 19：00～翌9：00 | G22: 1日日当たり
A23: 特殊作業員 | B23: 職長1 6.0AF２ MR1 TR1 | C23: 5 | D23: 人工 | E23: =26700*1.35 -> 36045 | F23: =SUM(C23*E23) -> 180225 | G23: 機械オペ
A24: 普通作業員 | B24: スコップ2 レーキ2 誘導員1 監視員1 | C24: 6 | D24: 人工 | E24: =23600*1.35 -> 31860 | F24: =SUM(C24*E24) -> 191160
A25: 小物機械費 | B25: 清掃 はつり 転圧機械 コアマシーン | C25: 1 | D25: 日/式 | E25: 33000 | F25: =SUM(C25*E25) -> 33000
A26: 車両費 | B26: Wキャブ 3ｔダンプ 連絡車2 | C26: 1 | D26: 日/式 | E26: 20000 | F26: =SUM(C26*E26) -> 20000
A27: 交通費 | B27: 高速代 燃料費 | C27: 1 | D27: 日/式 | E27: 22000 | F27: =SUM(C27*E27) -> 22000
A28: 重機機械費 | B28: 6.0AF MR TR 0.15BH AFセンサー | C28: 1 | D28: 日/式 | E28: 95000 | F28: =SUM(C28*E28) -> 95000 | G28: 稼働月１０日以上
A29: 重機燃料費 | B29: 軽油 | C29: 1 | D29: 日/式 | E29: 15000 | F29: =SUM(C29*E29) -> 15000
A30: 残業 | B30: 作業時間8ｈを超えた場合 | C30: 1 | D30: ｈ | E30: 4300 | G30: 別途請求
A31: 夜間照明ご用意願います。
A34: 労働災害防止対策費 | C34: 1 | D34: 式 | E34: =SUM(F23:F30)*0.004 -> 2225.54 | F34: =SUM(C34*E34) -> 2225.54
A35: 諸経費 | C35: 1 | D35: 式 | E35: =SUM(F23:F30)*0.15 -> 83457.75 | F35: =SUM(C35*E35) -> 83457.75
A36: 端数調整 | F36: -776 | G36: 社会保険料率 ＝15.938％
A37: 法定福利費 | C37: 1 | D37: 式 | E37: =SUM(F23:F24)*0.15 -> 55707.75 | F37: =SUM(C37*E37) -> 55707.75
A38: 2. 【合計】 | F38: =SUM(F23:F37) -> 697000.04 | L38: =L19+#REF! -> #REF!
A39: 内 訳 明 細 書 3 | I39: 業 者 名
A40: 名 称 | B40: 規 格 | C40: 数 量 | D40: 単 位 | E40: 単 価 | F40: 金 額 | G40: 備 考 | I40: 数 量 | J40: 単 位 | K40: 単 価 | L40: 金 額
A41: 3. 切削オーバーレイ工(土工部) | B41: 夜間施工 19：00～翌5：00 | G41: 1日日当たり
A42: 特殊作業員 | B42: 職長1 6.0AF２ MR1 TR1 | C42: 5 | D42: 人工 | E42: =26700*1.35 -> 36045 | F42: =SUM(C42*E42) -> 180225 | G42: 機械オペ | L42: =SUM(I42*K42) -> 0
A43: 普通作業員 | B43: スコップ2 レーキ2 誘導員1 監視員1 | C43: 6 | D43: 人工 | E43: =23600*1.35 -> 31860 | F43: =SUM(C43*E43) -> 191160
A44: 小物機械費 | B44: 清掃 はつり 転圧機械 コアマシーン | C44: 1 | D44: 日/式 | E44: 33000 | F44: =SUM(C44*E44) -> 33000 | L44: =SUM(I44*K44) -> 0
A45: 車両費 | B45: Wキャブ 3ｔダンプ 連絡車2 | C45: 1 | D45: 日/式 | E45: 20000 | F45: =SUM(C45*E45) -> 20000
...
